Workbook

Sheet Summary
A1: Swastika Signal (reconstructed) - backtest summary, MCX 1h, Jan 2025 - Sep 2026
A3: Inputs (edit the yellow cells)
A4: Lots per trade | B4: 1 | C4: Number of standard lots per trade. All P&L scales with this.
A5: Silver: ₹ per point per lot | B5: 30 | C5: MCX SILVER lot = 30 kg, quoted in ₹/kg.
A6: Gold: ₹ per point per lot | B6: 100 | C6: MCX GOLD lot = 1 kg, quoted in ₹/10 g.
A8: Results by strategy (all formulas)
A9: Metal | B9: Strategy | C9: Description | D9: Trades | E9: Wins | F9: Win % | G9: Net P&L (₹) | H9: 2025 net (₹) | I9: 2026 net (₹) | J9: Avg win (₹) | K9: Avg loss (₹) | L9: Profit factor | M9: Max drawdown (₹) | N9: Profitable months % | O9: Best month (₹) | P9: Worst month (₹) | Q9: Trades / month
A10: SILVER | B10: V0 | C10: Real Buy/Sell, always in | D10: =COUNTIFS(Trades!$A$2:$A$2161,A10,Trades!$B$2:$B$2161,B10) -> 69 | E10: =COUNTIFS(Trades!$A$2:$A$2161,A10,Trades!$B$2:$B$2161,B10,Trades!$M$2:$M$2161,1) -> 33 | F10: =IF(D10=0,"",E10/D10) -> 0.47826087 | G10: =SUMIFS(Trades!$K$2:$K$2161,Trades!$A$2:$A$2161,A10,Trades!$B$2:$B$2161,B10) -> 6378578.1 | H10: =SUMIFS(Trades!$K$2:$K$2161,Trades!$A$2:$A$2161,A10,Trades!$B$2:$B$2161,B10,Trades!$E$2:$E$2161,">="&DATE(2025,1,1),Trades!$E$2:$E$2161,"<"&DATE(2026,1,1)) -> 1718459.7 | I10: =SUMIFS(Trades!$K$2:$K$2161,Trades!$A$2:$A$2161,A10,Trades!$B$2:$B$2161,B10,Trades!$E$2:$E$2161,">="&DATE(2026,1,1)) -> 4660118.4 | J10: =IFERROR(AVERAGEIFS(Trades!$K$2:$K$2161,Trades!$A$2:$A$2161,A10,Trades!$B$2:$B$2161,B10,Trades!$K$2:$K$2161,">0"),0) -> 406739.05 | K10: =IFERROR(AVERAGEIFS(Trades!$K$2:$K$2161,Trades!$A$2:$A$2161,A10,Trades!$B$2:$B$2161,B10,Trades!$K$2:$K$2161,"<=0"),0) -> -195661.4 | L10: =IFERROR(SUMIFS(Trades!$K$2:$K$2161,Trades!$A$2:$A$2161,A10,Trades!$B$2:$B$2161,B10,Trades!$K$2:$K$2161,">0")/-SUMIFS(Trades!$K$2:$K$2161,Trades!$A$2:$A$2161,A10,Trades!$B$2:$B$2161,B10,Trades!$K$2:$K$2161,"<=0"),"no losses") -> 1.9055579 | M10: =_xlfn.MINIFS(Trades!$P$2:$P$2161,Trades!$A$2:$A$2161,A10,Trades!$B$2:$B$2161,B10) -> -1535198.1 | N10: =IFERROR(COUNTIF('Silver Monthly'!D$5:D$25,">0")/COUNTIF('Silver Monthly'!B$5:B$25,">0"),"") -> 0.61904762 | O10: =MAX('Silver Monthly'!D$5:D$25) -> 3432137.1 | P10: =MIN('Silver Monthly'!D$5:D$25) -> -795427.2 | Q10: =D10/COUNT('Silver Monthly'!$A$5:$A$25) -> 3.2857143
A11: SILVER | B11: V1 | C11: Day filter | D11: =COUNTIFS(Trades!$A$2:$A$2161,A11,Trades!$B$2:$B$2161,B11) -> 32 | E11: =COUNTIFS(Trades!$A$2:$A$2161,A11,Trades!$B$2:$B$2161,B11,Trades!$M$2:$M$2161,1) -> 19 | F11: =IF(D11=0,"",E11/D11) -> 0.59375 | G11: =SUMIFS(Trades!$K$2:$K$2161,Trades!$A$2:$A$2161,A11,Trades!$B$2:$B$2161,B11) -> 5793475.8 | H11: =SUMIFS(Trades!$K$2:$K$2161,Trades!$A$2:$A$2161,A11,Trades!$B$2:$B$2161,B11,Trades!$E$2:$E$2161,">="&DATE(2025,1,1),Trades!$E$2:$E$2161,"<"&DATE(2026,1,1)) -> 2697719.1 | I11: =SUMIFS(Trades!$K$2:$K$2161,Trades!$A$2:$A$2161,A11,Trades!$B$2:$B$2161,B11,Trades!$E$2:$E$2161,">="&DATE(2026,1,1)) -> 3095756.7 | J11: =IFERROR(AVERAGEIFS(Trades!$K$2:$K$2161,Trades!$A$2:$A$2161,A11,Trades!$B$2:$B$2161,B11,Trades!$K$2:$K$2161,">0"),0) -> 398927.31 | K11: =IFERROR(AVERAGEIFS(Trades!$K$2:$K$2161,Trades!$A$2:$A$2161,A11,Trades!$B$2:$B$2161,B11,Trades!$K$2:$K$2161,"<=0"),0) -> -137395.62 | L11: =IFERROR(SUMIFS(Trades!$K$2:$K$2161,Trades!$A$2:$A$2161,A11,Trades!$B$2:$B$2161,B11,Trades!$K$2:$K$2161,">0")/-SUMIFS(Trades!$K$2:$K$2161,Trades!$A$2:$A$2161,A11,Trades!$B$2:$B$2161,B11,Trades!$K$2:$K$2161,"<=0"),"no losses") -> 4.2435677 | M11: =_xlfn.MINIFS(Trades!$P$2:$P$2161,Trades!$A$2:$A$2161,A11,Trades!$B$2:$B$2161,B11) -> -905013.9 | N11: =IFERROR(COUNTIF('Silver Monthly'!H$5:H$25,">0")/COUNTIF('Silver Monthly'!F$5:F$25,">0"),"") -> 0.63157895 | O11: =MAX('Silver Monthly'!H$5:H$25) -> 1803102.9 | P11: =MIN('Silver Monthly'!H$5:H$25) -> -528600.9 | Q11: =D11/COUNT('Silver Monthly'!$A$5:$A$25) -> 1.5238095
A12: SILVER | B12: W8 | C12: Day filter + profit lock | D12: =COUNTIFS(Trades!$A$2:$A$2161,A12,Trades!$B$2:$B$2161,B12) -> 32 | E12: =COUNTIFS(Trades!$A$2:$A$2161,A12,Trades!$B$2:$B$2161,B12,Trades!$M$2:$M$2161,1) -> 25 | F12: =IF(D12=0,"",E12/D12) -> 0.78125 | G12: =SUMIFS(Trades!$K$2:$K$2161,Trades!$A$2:$A$2161,A12,Trades!$B$2:$B$2161,B12) -> 5072715.3 | H12: =SUMIFS(Trades!$K$2:$K$2161,Trades!$A$2:$A$2161,A12,Trades!$B$2:$B$2161,B12,Trades!$E$2:$E$2161,">="&DATE(2025,1,1),Trades!$E$2:$E$2161,"<"&DATE(2026,1,1)) -> 2657337.3 | I12: =SUMIFS(Trades!$K$2:$K$2161,Trades!$A$2:$A$2161,A12,Trades!$B$2:$B$2161,B12,Trades!$E$2:$E$2161,">="&DATE(2026,1,1)) -> 2415378 | J12: =IFERROR(AVERAGEIFS(Trades!$K$2:$K$2161,Trades!$A$2:$A$2161,A12,Trades!$B$2:$B$2161,B12,Trades!$K$2:$K$2161,">0"),0) -> 256761.05 | K12: =IFERROR(AVERAGEIFS(Trades!$K$2:$K$2161,Trades!$A$2:$A$2161,A12,Trades!$B$2:$B$2161,B12,Trades!$K$2:$K$2161,"<=0"),0) -> -192330.13 | L12: =IFERROR(SUMIFS(Trades!$K$2:$K$2161,Trades!$A$2:$A$2161,A12,Trades!$B$2:$B$2161,B12,Trades!$K$2:$K$2161,">0")/-SUMIFS(Trades!$K$2:$K$2161,Trades!$A$2:$A$2161,A12,Trades!$B$2:$B$2161,B12,Trades!$K$2:$K$2161,"<=0"),"no losses") -> 4.7678632 | M12: =_xlfn.MINIFS(Trades!$P$2:$P$2161,Trades!$A$2:$A$2161,A12,Trades!$B$2:$B$2161,B12) -> -803221.2 | N12: =IFERROR(COUNTIF('Silver Monthly'!L$5:L$25,">0")/COUNTIF('Silver Monthly'!J$5:J$25,">0"),"") -> 0.63157895 | O12: =MAX('Silver Monthly'!L$5:L$25) -> 1691348.4 | P12: =MIN('Silver Monthly'!L$5:L$25) -> -493147.5 | Q12: =D12/COUNT('Silver Monthly'!$A$5:$A$25) -> 1.5238095
A13: SILVER | B13: W8C | C13: Day + lock + 1-bar confirm | D13: =COUNTIFS(Trades!$A$2:$A$2161,A13,Trades!$B$2:$B$2161,B13) -> 16 | E13: =COUNTIFS(Trades!$A$2:$A$2161,A13,Trades!$B$2:$B$2161,B13,Trades!$M$2:$M$2161,1) -> 15 | F13: =IF(D13=0,"",E13/D13) -> 0.9375 | G13: =SUMIFS(Trades!$K$2:$K$2161,Trades!$A$2:$A$2161,A13,Trades!$B$2:$B$2161,B13) -> 3316208.4 | H13: =SUMIFS(Trades!$K$2:$K$2161,Trades!$A$2:$A$2161,A13,Trades!$B$2:$B$2161,B13,Trades!$E$2:$E$2161,">="&DATE(2025,1,1),Trades!$E$2:$E$2161,"<"&DATE(2026,1,1)) -> 1178374.8 | I13: =SUMIFS(Trades!$K$2:$K$2161,Trades!$A$2:$A$2161,A13,Trades!$B$2:$B$2161,B13,Trades!$E$2:$E$2161,">="&DATE(2026,1,1)) -> 2137833.6 | J13: =IFERROR(AVERAGEIFS(Trades!$K$2:$K$2161,Trades!$A$2:$A$2161,A13,Trades!$B$2:$B$2161,B13,Trades!$K$2:$K$2161,">0"),0) -> 232949.48 | K13: =IFERROR(AVERAGEIFS(Trades!$K$2:$K$2161,Trades!$A$2:$A$2161,A13,Trades!$B$2:$B$2161,B13,Trades!$K$2:$K$2161,"<=0"),0) -> -178033.8 | L13: =IFERROR(SUMIFS(Trades!$K$2:$K$2161,Trades!$A$2:$A$2161,A13,Trades!$B$2:$B$2161,B13,Trades!$K$2:$K$2161,">0")/-SUMIFS(Trades!$K$2:$K$2161,Trades!$A$2:$A$2161,A13,Trades!$B$2:$B$2161,B13,Trades!$K$2:$K$2161,"<=0"),"no losses") -> 19.626847 | M13: =_xlfn.MINIFS(Trades!$P$2:$P$2161,Trades!$A$2:$A$2161,A13,Trades!$B$2:$B$2161,B13) -> -178033.8 | N13: =IFERROR(COUNTIF('Silver Monthly'!P$5:P$25,">0")/COUNTIF('Silver Monthly'!N$5:N$25,">0"),"") -> 0.92307692 | O13: =MAX('Silver Monthly'!P$5:P$25) -> 1529008.2 | P13: =MIN('Silver Monthly'!P$5:P$25) -> -148735.5 | Q13: =D13/COUNT('Silver Monthly'!$A$5:$A$25) -> 0.76190476
A14: SILVER | B14: T6 | C14: W8, faster band x3/x4 (1h) | D14: =COUNTIFS(Trades!$A$2:$A$2161,A14,Trades!$B$2:$B$2161,B14) -> 55 | E14: =COUNTIFS(Trades!$A$2:$A$2161,A14,Trades!$B$2:$B$2161,B14,Trades!$M$2:$M$2161,1) -> 36 | F14: =IF(D14=0,"",E14/D14) -> 0.65454545 | G14: =SUMIFS(Trades!$K$2:$K$2161,Trades!$A$2:$A$2161,A14,Trades!$B$2:$B$2161,B14) -> 5244862.2 | H14: =SUMIFS(Trades!$K$2:$K$2161,Trades!$A$2:$A$2161,A14,Trades!$B$2:$B$2161,B14,Trades!$E$2:$E$2161,">="&DATE(2025,1,1),Trades!$E$2:$E$2161,"<"&DATE(2026,1,1)) -> 2729003.7 | I14: =SUMIFS(Trades!$K$2:$K$2161,Trades!$A$2:$A$2161,A14,Trades!$B$2:$B$2161,B14,Trades!$E$2:$E$2161,">="&DATE(2026,1,1)) -> 2515858.5 | J14: =IFERROR(AVERAGEIFS(Trades!$K$2:$K$2161,Trades!$A$2:$A$2161,A14,Trades!$B$2:$B$2161,B14,Trades!$K$2:$K$2161,">0"),0) -> 220525.43 | K14: =IFERROR(AVERAGEIFS(Trades!$K$2:$K$2161,Trades!$A$2:$A$2161,A14,Trades!$B$2:$B$2161,B14,Trades!$K$2:$K$2161,"<=0"),0) -> -141792.28 | L14: =IFERROR(SUMIFS(Trades!$K$2:$K$2161,Trades!$A$2:$A$2161,A14,Trades!$B$2:$B$2161,B14,Trades!$K$2:$K$2161,">0")/-SUMIFS(Trades!$K$2:$K$2161,Trades!$A$2:$A$2161,A14,Trades!$B$2:$B$2161,B14,Trades!$K$2:$K$2161,"<=0"),"no losses") -> 2.9468293 | M14: =_xlfn.MINIFS(Trades!$P$2:$P$2161,Trades!$A$2:$A$2161,A14,Trades!$B$2:$B$2161,B14) -> -1133730.6 | N14: =IFERROR(COUNTIF('Silver Monthly'!T$5:T$25,">0")/COUNTIF('Silver Monthly'!R$5:R$25,">0"),"") -> 0.55 | O14: =MAX('Silver Monthly'!T$5:T$25) -> 3074079 | P14: =MIN('Silver Monthly'!T$5:T$25) -> -376678.5 | Q14: =D14/COUNT('Silver Monthly'!$A$5:$A$25) -> 2.6190476
A15: SILVER | B15: T7 | C15: W8 on 30m + trend re-entry | D15: =COUNTIFS(Trades!$A$2:$A$2161,A15,Trades!$B$2:$B$2161,B15) -> 73 | E15: =COUNTIFS(Trades!$A$2:$A$2161,A15,Trades!$B$2:$B$2161,B15,Trades!$M$2:$M$2161,1) -> 52 | F15: =IF(D15=0,"",E15/D15) -> 0.71232877 | G15: =SUMIFS(Trades!$K$2:$K$2161,Trades!$A$2:$A$2161,A15,Trades!$B$2:$B$2161,B15) -> 6679868.7 | H15: =SUMIFS(Trades!$K$2:$K$2161,Trades!$A$2:$A$2161,A15,Trades!$B$2:$B$2161,B15,Trades!$E$2:$E$2161,">="&DATE(2025,1,1),Trades!$E$2:$E$2161,"<"&DATE(2026,1,1)) -> 3000381.3 | I15: =SUMIFS(Trades!$K$2:$K$2161,Trades!$A$2:$A$2161,A15,Trades!$B$2:$B$2161,B15,Trades!$E$2:$E$2161,">="&DATE(2026,1,1)) -> 3679487.4 | J15: =IFERROR(AVERAGEIFS(Trades!$K$2:$K$2161,Trades!$A$2:$A$2161,A15,Trades!$B$2:$B$2161,B15,Trades!$K$2:$K$2161,">0"),0) -> 194114.15 | K15: =IFERROR(AVERAGEIFS(Trades!$K$2:$K$2161,Trades!$A$2:$A$2161,A15,Trades!$B$2:$B$2161,B15,Trades!$K$2:$K$2161,"<=0"),0) -> -162574.63 | L15: =IFERROR(SUMIFS(Trades!$K$2:$K$2161,Trades!$A$2:$A$2161,A15,Trades!$B$2:$B$2161,B15,Trades!$K$2:$K$2161,">0")/-SUMIFS(Trades!$K$2:$K$2161,Trades!$A$2:$A$2161,A15,Trades!$B$2:$B$2161,B15,Trades!$K$2:$K$2161,"<=0"),"no losses") -> 2.9565721 | M15: =_xlfn.MINIFS(Trades!$P$2:$P$2161,Trades!$A$2:$A$2161,A15,Trades!$B$2:$B$2161,B15) -> -1200000.3 | N15: =IFERROR(COUNTIF('Silver Monthly'!X$5:X$25,">0")/COUNTIF('Silver Monthly'!V$5:V$25,">0"),"") -> 0.6 | O15: =MAX('Silver Monthly'!X$5:X$25) -> 3048620.7 | P15: =MIN('Silver Monthly'!X$5:X$25) -> -776022 | Q15: =D15/COUNT('Silver Monthly'!$A$5:$A$25) -> 3.4761905
A16: SILVER | B16: U1 | C16: W8 on 15m chart | D16: =COUNTIFS(Trades!$A$2:$A$2161,A16,Trades!$B$2:$B$2161,B16) -> 129 | E16: =COUNTIFS(Trades!$A$2:$A$2161,A16,Trades!$B$2:$B$2161,B16,Trades!$M$2:$M$2161,1) -> 81 | F16: =IF(D16=0,"",E16/D16) -> 0.62790698 | G16: =SUMIFS(Trades!$K$2:$K$2161,Trades!$A$2:$A$2161,A16,Trades!$B$2:$B$2161,B16) -> 4918910.4 | H16: =SUMIFS(Trades!$K$2:$K$2161,Trades!$A$2:$A$2161,A16,Trades!$B$2:$B$2161,B16,Trades!$E$2:$E$2161,">="&DATE(2025,1,1),Trades!$E$2:$E$2161,"<"&DATE(2026,1,1)) -> 1787140.8 | I16: =SUMIFS(Trades!$K$2:$K$2161,Trades!$A$2:$A$2161,A16,Trades!$B$2:$B$2161,B16,Trades!$E$2:$E$2161,">="&DATE(2026,1,1)) -> 3131769.6 | J16: =IFERROR(AVERAGEIFS(Trades!$K$2:$K$2161,Trades!$A$2:$A$2161,A16,Trades!$B$2:$B$2161,B16,Trades!$K$2:$K$2161,">0"),0) -> 127477.23 | K16: =IFERROR(AVERAGEIFS(Trades!$K$2:$K$2161,Trades!$A$2:$A$2161,A16,Trades!$B$2:$B$2161,B16,Trades!$K$2:$K$2161,"<=0"),0) -> -112640.53 | L16: =IFERROR(SUMIFS(Trades!$K$2:$K$2161,Trades!$A$2:$A$2161,A16,Trades!$B$2:$B$2161,B16,Trades!$K$2:$K$2161,">0")/-SUMIFS(Trades!$K$2:$K$2161,Trades!$A$2:$A$2161,A16,Trades!$B$2:$B$2161,B16,Trades!$K$2:$K$2161,"<=0"),"no losses") -> 1.9097729 | M16: =_xlfn.MINIFS(Trades!$P$2:$P$2161,Trades!$A$2:$A$2161,A16,Trades!$B$2:$B$2161,B16) -> -836158.2 | N16: =IFERROR(COUNTIF('Silver Monthly'!AB$5:AB$25,">0")/COUNTIF('Silver Monthly'!Z$5:Z$25,">0"),"") -> 0.6 | O16: =MAX('Silver Monthly'!AB$5:AB$25) -> 2450633.4 | P16: =MIN('Silver Monthly'!AB$5:AB$25) -> -187527.3 | Q16: =D16/COUNT('Silver Monthly'!$A$5:$A$25) -> 6.1428571
A17: SILVER | B17: U9 | C17: W8 on 5m chart | D17: =COUNTIFS(Trades!$A$2:$A$2161,A17,Trades!$B$2:$B$2161,B17) -> 340 | E17: =COUNTIFS(Trades!$A$2:$A$2161,A17,Trades!$B$2:$B$2161,B17,Trades!$M$2:$M$2161,1) -> 218 | F17: =IF(D17=0,"",E17/D17) -> 0.64117647 | G17: =SUMIFS(Trades!$K$2:$K$2161,Trades!$A$2:$A$2161,A17,Trades!$B$2:$B$2161,B17) -> 9616894.2 | H17: =SUMIFS(Trades!$K$2:$K$2161,Trades!$A$2:$A$2161,A17,Trades!$B$2:$B$2161,B17,Trades!$E$2:$E$2161,">="&DATE(2025,1,1),Trades!$E$2:$E$2161,"<"&DATE(2026,1,1)) -> 2313441.9 | I17: =SUMIFS(Trades!$K$2:$K$2161,Trades!$A$2:$A$2161,A17,Trades!$B$2:$B$2161,B17,Trades!$E$2:$E$2161,">="&DATE(2026,1,1)) -> 7303452.3 | J17: =IFERROR(AVERAGEIFS(Trades!$K$2:$K$2161,Trades!$A$2:$A$2161,A17,Trades!$B$2:$B$2161,B17,Trades!$K$2:$K$2161,">0"),0) -> 77076.981 | K17: =IFERROR(AVERAGEIFS(Trades!$K$2:$K$2161,Trades!$A$2:$A$2161,A17,Trades!$B$2:$B$2161,B17,Trades!$K$2:$K$2161,"<=0"),0) -> -58900.719 | L17: =IFERROR(SUMIFS(Trades!$K$2:$K$2161,Trades!$A$2:$A$2161,A17,Trades!$B$2:$B$2161,B17,Trades!$K$2:$K$2161,">0")/-SUMIFS(Trades!$K$2:$K$2161,Trades!$A$2:$A$2161,A17,Trades!$B$2:$B$2161,B17,Trades!$K$2:$K$2161,"<=0"),"no losses") -> 2.3383029 | M17: =_xlfn.MINIFS(Trades!$P$2:$P$2161,Trades!$A$2:$A$2161,A17,Trades!$B$2:$B$2161,B17) -> -918885.6 | N17: =IFERROR(COUNTIF('Silver Monthly'!AF$5:AF$25,">0")/COUNTIF('Silver Monthly'!AD$5:AD$25,">0"),"") -> 0.71428571 | O17: =MAX('Silver Monthly'!AF$5:AF$25) -> 3535317.3 | P17: =MIN('Silver Monthly'!AF$5:AF$25) -> -225352.5 | Q17: =D17/COUNT('Silver Monthly'!$A$5:$A$25) -> 16.190476
A18: SILVER | B18: Q1 | C18: 5m: 1h filter, lock 0.15R@0.3R, re-entry 120 | D18: =COUNTIFS(Trades!$A$2:$A$2161,A18,Trades!$B$2:$B$2161,B18) -> 340 | E18: =COUNTIFS(Trades!$A$2:$A$2161,A18,Trades!$B$2:$B$2161,B18,Trades!$M$2:$M$2161,1) -> 260 | F18: =IF(D18=0,"",E18/D18) -> 0.76470588 | G18: =SUMIFS(Trades!$K$2:$K$2161,Trades!$A$2:$A$2161,A18,Trades!$B$2:$B$2161,B18) -> 7429502.1 | H18: =SUMIFS(Trades!$K$2:$K$2161,Trades!$A$2:$A$2161,A18,Trades!$B$2:$B$2161,B18,Trades!$E$2:$E$2161,">="&DATE(2025,1,1),Trades!$E$2:$E$2161,"<"&DATE(2026,1,1)) -> 1742147.7 | I18: =SUMIFS(Trades!$K$2:$K$2161,Trades!$A$2:$A$2161,A18,Trades!$B$2:$B$2161,B18,Trades!$E$2:$E$2161,">="&DATE(2026,1,1)) -> 5687354.4 | J18: =IFERROR(AVERAGEIFS(Trades!$K$2:$K$2161,Trades!$A$2:$A$2161,A18,Trades!$B$2:$B$2161,B18,Trades!$K$2:$K$2161,">0"),0) -> 45942.196 | K18: =IFERROR(AVERAGEIFS(Trades!$K$2:$K$2161,Trades!$A$2:$A$2161,A18,Trades!$B$2:$B$2161,B18,Trades!$K$2:$K$2161,"<=0"),0) -> -56443.361 | L18: =IFERROR(SUMIFS(Trades!$K$2:$K$2161,Trades!$A$2:$A$2161,A18,Trades!$B$2:$B$2161,B18,Trades!$K$2:$K$2161,">0")/-SUMIFS(Trades!$K$2:$K$2161,Trades!$A$2:$A$2161,A18,Trades!$B$2:$B$2161,B18,Trades!$K$2:$K$2161,"<=0"),"no losses") -> 2.6453445 | M18: =_xlfn.MINIFS(Trades!$P$2:$P$2161,Trades!$A$2:$A$2161,A18,Trades!$B$2:$B$2161,B18) -> -685901.4 | N18: =IFERROR(COUNTIF('Silver Monthly'!AJ$5:AJ$25,">0")/COUNTIF('Silver Monthly'!AH$5:AH$25,">0"),"") -> 0.75 | O18: =MAX('Silver Monthly'!AJ$5:AJ$25) -> 2114211.9 | P18: =MIN('Silver Monthly'!AJ$5:AJ$25) -> -134557.2 | Q18: =D18/COUNT('Silver Monthly'!$A$5:$A$25) -> 16.190476
A19: GOLD | B19: V0 | C19: Real Buy/Sell, always in | D19: =COUNTIFS(Trades!$A$2:$A$2161,A19,Trades!$B$2:$B$2161,B19) -> 59 | E19: =COUNTIFS(Trades!$A$2:$A$2161,A19,Trades!$B$2:$B$2161,B19,Trades!$M$2:$M$2161,1) -> 31 | F19: =IF(D19=0,"",E19/D19) -> 0.52542373 | G19: =SUMIFS(Trades!$K$2:$K$2161,Trades!$A$2:$A$2161,A19,Trades!$B$2:$B$2161,B19) -> 9564695 | H19: =SUMIFS(Trades!$K$2:$K$2161,Trades!$A$2:$A$2161,A19,Trades!$B$2:$B$2161,B19,Trades!$E$2:$E$2161,">="&DATE(2025,1,1),Trades!$E$2:$E$2161,"<"&DATE(2026,1,1)) -> 4038831 | I19: =SUMIFS(Trades!$K$2:$K$2161,Trades!$A$2:$A$2161,A19,Trades!$B$2:$B$2161,B19,Trades!$E$2:$E$2161,">="&DATE(2026,1,1)) -> 5525864 | J19: =IFERROR(AVERAGEIFS(Trades!$K$2:$K$2161,Trades!$A$2:$A$2161,A19,Trades!$B$2:$B$2161,B19,Trades!$K$2:$K$2161,">0"),0) -> 482994.13 | K19: =IFERROR(AVERAGEIFS(Trades!$K$2:$K$2161,Trades!$A$2:$A$2161,A19,Trades!$B$2:$B$2161,B19,Trades!$K$2:$K$2161,"<=0"),0) -> -193147.25 | L19: =IFERROR(SUMIFS(Trades!$K$2:$K$2161,Trades!$A$2:$A$2161,A19,Trades!$B$2:$B$2161,B19,Trades!$K$2:$K$2161,">0")/-SUMIFS(Trades!$K$2:$K$2161,Trades!$A$2:$A$2161,A19,Trades!$B$2:$B$2161,B19,Trades!$K$2:$K$2161,"<=0"),"no losses") -> 2.7685794 | M19: =_xlfn.MINIFS(Trades!$P$2:$P$2161,Trades!$A$2:$A$2161,A19,Trades!$B$2:$B$2161,B19) -> -1112560 | N19: =IFERROR(COUNTIF('Gold Monthly'!D$5:D$25,">0")/COUNTIF('Gold Monthly'!B$5:B$25,">0"),"") -> 0.75 | O19: =MAX('Gold Monthly'!D$5:D$25) -> 2723501 | P19: =MIN('Gold Monthly'!D$5:D$25) -> -792407 | Q19: =D19/COUNT('Gold Monthly'!$A$5:$A$25) -> 2.8095238
A20: GOLD | B20: V1 | C20: Day filter | D20: =COUNTIFS(Trades!$A$2:$A$2161,A20,Trades!$B$2:$B$2161,B20) -> 28 | E20: =COUNTIFS(Trades!$A$2:$A$2161,A20,Trades!$B$2:$B$2161,B20,Trades!$M$2:$M$2161,1) -> 18 | F20: =IF(D20=0,"",E20/D20) -> 0.64285714 | G20: =SUMIFS(Trades!$K$2:$K$2161,Trades!$A$2:$A$2161,A20,Trades!$B$2:$B$2161,B20) -> 7134101 | H20: =SUMIFS(Trades!$K$2:$K$2161,Trades!$A$2:$A$2161,A20,Trades!$B$2:$B$2161,B20,Trades!$E$2:$E$2161,">="&DATE(2025,1,1),Trades!$E$2:$E$2161,"<"&DATE(2026,1,1)) -> 4042473 | I20: =SUMIFS(Trades!$K$2:$K$2161,Trades!$A$2:$A$2161,A20,Trades!$B$2:$B$2161,B20,Trades!$E$2:$E$2161,">="&DATE(2026,1,1)) -> 3091628 | J20: =IFERROR(AVERAGEIFS(Trades!$K$2:$K$2161,Trades!$A$2:$A$2161,A20,Trades!$B$2:$B$2161,B20,Trades!$K$2:$K$2161,">0"),0) -> 495598.56 | K20: =IFERROR(AVERAGEIFS(Trades!$K$2:$K$2161,Trades!$A$2:$A$2161,A20,Trades!$B$2:$B$2161,B20,Trades!$K$2:$K$2161,"<=0"),0) -> -178667.3 | L20: =IFERROR(SUMIFS(Trades!$K$2:$K$2161,Trades!$A$2:$A$2161,A20,Trades!$B$2:$B$2161,B20,Trades!$K$2:$K$2161,">0")/-SUMIFS(Trades!$K$2:$K$2161,Trades!$A$2:$A$2161,A20,Trades!$B$2:$B$2161,B20,Trades!$K$2:$K$2161,"<=0"),"no losses") -> 4.9929528 | M20: =_xlfn.MINIFS(Trades!$P$2:$P$2161,Trades!$A$2:$A$2161,A20,Trades!$B$2:$B$2161,B20) -> -770980 | N20: =IFERROR(COUNTIF('Gold Monthly'!H$5:H$25,">0")/COUNTIF('Gold Monthly'!F$5:F$25,">0"),"") -> 0.70588235 | O20: =MAX('Gold Monthly'!H$5:H$25) -> 1995214 | P20: =MIN('Gold Monthly'!H$5:H$25) -> -762014 | Q20: =D20/COUNT('Gold Monthly'!$A$5:$A$25) -> 1.3333333
A21: GOLD | B21: W8 | C21: Day filter + profit lock | D21: =COUNTIFS(Trades!$A$2:$A$2161,A21,Trades!$B$2:$B$2161,B21) -> 28 | E21: =COUNTIFS(Trades!$A$2:$A$2161,A21,Trades!$B$2:$B$2161,B21,Trades!$M$2:$M$2161,1) -> 23 | F21: =IF(D21=0,"",E21/D21) -> 0.82142857 | G21: =SUMIFS(Trades!$K$2:$K$2161,Trades!$A$2:$A$2161,A21,Trades!$B$2:$B$2161,B21) -> 5560961 | H21: =SUMIFS(Trades!$K$2:$K$2161,Trades!$A$2:$A$2161,A21,Trades!$B$2:$B$2161,B21,Trades!$E$2:$E$2161,">="&DATE(2025,1,1),Trades!$E$2:$E$2161,"<"&DATE(2026,1,1)) -> 4313633 | I21: =SUMIFS(Trades!$K$2:$K$2161,Trades!$A$2:$A$2161,A21,Trades!$B$2:$B$2161,B21,Trades!$E$2:$E$2161,">="&DATE(2026,1,1)) -> 1247328 | J21: =IFERROR(AVERAGEIFS(Trades!$K$2:$K$2161,Trades!$A$2:$A$2161,A21,Trades!$B$2:$B$2161,B21,Trades!$K$2:$K$2161,">0"),0) -> 307792.61 | K21: =IFERROR(AVERAGEIFS(Trades!$K$2:$K$2161,Trades!$A$2:$A$2161,A21,Trades!$B$2:$B$2161,B21,Trades!$K$2:$K$2161,"<=0"),0) -> -303653.8 | L21: =IFERROR(SUMIFS(Trades!$K$2:$K$2161,Trades!$A$2:$A$2161,A21,Trades!$B$2:$B$2161,B21,Trades!$K$2:$K$2161,">0")/-SUMIFS(Trades!$K$2:$K$2161,Trades!$A$2:$A$2161,A21,Trades!$B$2:$B$2161,B21,Trades!$K$2:$K$2161,"<=0"),"no losses") -> 4.6626981 | M21: =_xlfn.MINIFS(Trades!$P$2:$P$2161,Trades!$A$2:$A$2161,A21,Trades!$B$2:$B$2161,B21) -> -762014 | N21: =IFERROR(COUNTIF('Gold Monthly'!L$5:L$25,">0")/COUNTIF('Gold Monthly'!J$5:J$25,">0"),"") -> 0.76470588 | O21: =MAX('Gold Monthly'!L$5:L$25) -> 1298355 | P21: =MIN('Gold Monthly'!L$5:L$25) -> -762014 | Q21: =D21/COUNT('Gold Monthly'!$A$5:$A$25) -> 1.3333333
A22: GOLD | B22: W8C | C22: Day + lock + 1-bar confirm | D22: =COUNTIFS(Trades!$A$2:$A$2161,A22,Trades!$B$2:$B$2161,B22) -> 18 | E22: =COUNTIFS(Trades!$A$2:$A$2161,A22,Trades!$B$2:$B$2161,B22,Trades!$M$2:$M$2161,1) -> 16 | F22: =IF(D22=0,"",E22/D22) -> 0.88888889 | G22: =SUMIFS(Trades!$K$2:$K$2161,Trades!$A$2:$A$2161,A22,Trades!$B$2:$B$2161,B22) -> 4234572 | H22: =SUMIFS(Trades!$K$2:$K$2161,Trades!$A$2:$A$2161,A22,Trades!$B$2:$B$2161,B22,Trades!$E$2:$E$2161,">="&DATE(2025,1,1),Trades!$E$2:$E$2161,"<"&DATE(2026,1,1)) -> 2135607 | I22: =SUMIFS(Trades!$K$2:$K$2161,Trades!$A$2:$A$2161,A22,Trades!$B$2:$B$2161,B22,Trades!$E$2:$E$2161,">="&DATE(2026,1,1)) -> 2098965 | J22: =IFERROR(AVERAGEIFS(Trades!$K$2:$K$2161,Trades!$A$2:$A$2161,A22,Trades!$B$2:$B$2161,B22,Trades!$K$2:$K$2161,">0"),0) -> 290415.38 | K22: =IFERROR(AVERAGEIFS(Trades!$K$2:$K$2161,Trades!$A$2:$A$2161,A22,Trades!$B$2:$B$2161,B22,Trades!$K$2:$K$2161,"<=0"),0) -> -206037 | L22: =IFERROR(SUMIFS(Trades!$K$2:$K$2161,Trades!$A$2:$A$2161,A22,Trades!$B$2:$B$2161,B22,Trades!$K$2:$K$2161,">0")/-SUMIFS(Trades!$K$2:$K$2161,Trades!$A$2:$A$2161,A22,Trades!$B$2:$B$2161,B22,Trades!$K$2:$K$2161,"<=0"),"no losses") -> 11.276242 | M22: =_xlfn.MINIFS(Trades!$P$2:$P$2161,Trades!$A$2:$A$2161,A22,Trades!$B$2:$B$2161,B22) -> -295056 | N22: =IFERROR(COUNTIF('Gold Monthly'!P$5:P$25,">0")/COUNTIF('Gold Monthly'!N$5:N$25,">0"),"") -> 0.85714286 | O22: =MAX('Gold Monthly'!P$5:P$25) -> 1097317 | P22: =MIN('Gold Monthly'!P$5:P$25) -> -295056 | Q22: =D22/COUNT('Gold Monthly'!$A$5:$A$25) -> 0.85714286
A23: GOLD | B23: T6 | C23: W8, faster band x3/x4 (1h) | D23: =COUNTIFS(Trades!$A$2:$A$2161,A23,Trades!$B$2:$B$2161,B23) -> 57 | E23: =COUNTIFS(Trades!$A$2:$A$2161,A23,Trades!$B$2:$B$2161,B23,Trades!$M$2:$M$2161,1) -> 40 | F23: =IF(D23=0,"",E23/D23) -> 0.70175439 | G23: =SUMIFS(Trades!$K$2:$K$2161,Trades!$A$2:$A$2161,A23,Trades!$B$2:$B$2161,B23) -> 3186182 | H23: =SUMIFS(Trades!$K$2:$K$2161,Trades!$A$2:$A$2161,A23,Trades!$B$2:$B$2161,B23,Trades!$E$2:$E$2161,">="&DATE(2025,1,1),Trades!$E$2:$E$2161,"<"&DATE(2026,1,1)) -> 2086070 | I23: =SUMIFS(Trades!$K$2:$K$2161,Trades!$A$2:$A$2161,A23,Trades!$B$2:$B$2161,B23,Trades!$E$2:$E$2161,">="&DATE(2026,1,1)) -> 1100112 | J23: =IFERROR(AVERAGEIFS(Trades!$K$2:$K$2161,Trades!$A$2:$A$2161,A23,Trades!$B$2:$B$2161,B23,Trades!$K$2:$K$2161,">0"),0) -> 175023.38 | K23: =IFERROR(AVERAGEIFS(Trades!$K$2:$K$2161,Trades!$A$2:$A$2161,A23,Trades!$B$2:$B$2161,B23,Trades!$K$2:$K$2161,"<=0"),0) -> -224397.24 | L23: =IFERROR(SUMIFS(Trades!$K$2:$K$2161,Trades!$A$2:$A$2161,A23,Trades!$B$2:$B$2161,B23,Trades!$K$2:$K$2161,">0")/-SUMIFS(Trades!$K$2:$K$2161,Trades!$A$2:$A$2161,A23,Trades!$B$2:$B$2161,B23,Trades!$K$2:$K$2161,"<=0"),"no losses") -> 1.8352263 | M23: =_xlfn.MINIFS(Trades!$P$2:$P$2161,Trades!$A$2:$A$2161,A23,Trades!$B$2:$B$2161,B23) -> -1267242 | N23: =IFERROR(COUNTIF('Gold Monthly'!T$5:T$25,">0")/COUNTIF('Gold Monthly'!R$5:R$25,">0"),"") -> 0.65 | O23: =MAX('Gold Monthly'!T$5:T$25) -> 1624917 | P23: =MIN('Gold Monthly'!T$5:T$25) -> -350577 | Q23: =D23/COUNT('Gold Monthly'!$A$5:$A$25) -> 2.7142857
A24: GOLD | B24: T7 | C24: W8 on 30m + trend re-entry | D24: =COUNTIFS(Trades!$A$2:$A$2161,A24,Trades!$B$2:$B$2161,B24) -> 75 | E24: =COUNTIFS(Trades!$A$2:$A$2161,A24,Trades!$B$2:$B$2161,B24,Trades!$M$2:$M$2161,1) -> 50 | F24: =IF(D24=0,"",E24/D24) -> 0.66666667 | G24: =SUMIFS(Trades!$K$2:$K$2161,Trades!$A$2:$A$2161,A24,Trades!$B$2:$B$2161,B24) -> 4137634 | H24: =SUMIFS(Trades!$K$2:$K$2161,Trades!$A$2:$A$2161,A24,Trades!$B$2:$B$2161,B24,Trades!$E$2:$E$2161,">="&DATE(2025,1,1),Trades!$E$2:$E$2161,"<"&DATE(2026,1,1)) -> 3290310 | I24: =SUMIFS(Trades!$K$2:$K$2161,Trades!$A$2:$A$2161,A24,Trades!$B$2:$B$2161,B24,Trades!$E$2:$E$2161,">="&DATE(2026,1,1)) -> 847324 | J24: =IFERROR(AVERAGEIFS(Trades!$K$2:$K$2161,Trades!$A$2:$A$2161,A24,Trades!$B$2:$B$2161,B24,Trades!$K$2:$K$2161,">0"),0) -> 212244.7 | K24: =IFERROR(AVERAGEIFS(Trades!$K$2:$K$2161,Trades!$A$2:$A$2161,A24,Trades!$B$2:$B$2161,B24,Trades!$K$2:$K$2161,"<=0"),0) -> -258984.04 | L24: =IFERROR(SUMIFS(Trades!$K$2:$K$2161,Trades!$A$2:$A$2161,A24,Trades!$B$2:$B$2161,B24,Trades!$K$2:$K$2161,">0")/-SUMIFS(Trades!$K$2:$K$2161,Trades!$A$2:$A$2161,A24,Trades!$B$2:$B$2161,B24,Trades!$K$2:$K$2161,"<=0"),"no losses") -> 1.6390562 | M24: =_xlfn.MINIFS(Trades!$P$2:$P$2161,Trades!$A$2:$A$2161,A24,Trades!$B$2:$B$2161,B24) -> -2147882 | N24: =IFERROR(COUNTIF('Gold Monthly'!X$5:X$25,">0")/COUNTIF('Gold Monthly'!V$5:V$25,">0"),"") -> 0.75 | O24: =MAX('Gold Monthly'!X$5:X$25) -> 1588734 | P24: =MIN('Gold Monthly'!X$5:X$25) -> -2147882 | Q24: =D24/COUNT('Gold Monthly'!$A$5:$A$25) -> 3.5714286
A25: GOLD | B25: U1 | C25: W8 on 15m chart | D25: =COUNTIFS(Trades!$A$2:$A$2161,A25,Trades!$B$2:$B$2161,B25) -> 123 | E25: =COUNTIFS(Trades!$A$2:$A$2161,A25,Trades!$B$2:$B$2161,B25,Trades!$M$2:$M$2161,1) -> 76 | F25: =IF(D25=0,"",E25/D25) -> 0.61788618 | G25: =SUMIFS(Trades!$K$2:$K$2161,Trades!$A$2:$A$2161,A25,Trades!$B$2:$B$2161,B25) -> 4161445 | H25: =SUMIFS(Trades!$K$2:$K$2161,Trades!$A$2:$A$2161,A25,Trades!$B$2:$B$2161,B25,Trades!$E$2:$E$2161,">="&DATE(2025,1,1),Trades!$E$2:$E$2161,"<"&DATE(2026,1,1)) -> 1946780 | I25: =SUMIFS(Trades!$K$2:$K$2161,Trades!$A$2:$A$2161,A25,Trades!$B$2:$B$2161,B25,Trades!$E$2:$E$2161,">="&DATE(2026,1,1)) -> 2214665 | J25: =IFERROR(AVERAGEIFS(Trades!$K$2:$K$2161,Trades!$A$2:$A$2161,A25,Trades!$B$2:$B$2161,B25,Trades!$K$2:$K$2161,">0"),0) -> 138609.12 | K25: =IFERROR(AVERAGEIFS(Trades!$K$2:$K$2161,Trades!$A$2:$A$2161,A25,Trades!$B$2:$B$2161,B25,Trades!$K$2:$K$2161,"<=0"),0) -> -135592.51 | L25: =IFERROR(SUMIFS(Trades!$K$2:$K$2161,Trades!$A$2:$A$2161,A25,Trades!$B$2:$B$2161,B25,Trades!$K$2:$K$2161,">0")/-SUMIFS(Trades!$K$2:$K$2161,Trades!$A$2:$A$2161,A25,Trades!$B$2:$B$2161,B25,Trades!$K$2:$K$2161,"<=0"),"no losses") -> 1.6529961 | M25: =_xlfn.MINIFS(Trades!$P$2:$P$2161,Trades!$A$2:$A$2161,A25,Trades!$B$2:$B$2161,B25) -> -1784258 | N25: =IFERROR(COUNTIF('Gold Monthly'!AB$5:AB$25,">0")/COUNTIF('Gold Monthly'!Z$5:Z$25,">0"),"") -> 0.55 | O25: =MAX('Gold Monthly'!AB$5:AB$25) -> 2870294 | P25: =MIN('Gold Monthly'!AB$5:AB$25) -> -956219 | Q25: =D25/COUNT('Gold Monthly'!$A$5:$A$25) -> 5.8571429
A26: GOLD | B26: U9 | C26: W8 on 5m chart | D26: =COUNTIFS(Trades!$A$2:$A$2161,A26,Trades!$B$2:$B$2161,B26) -> 342 | E26: =COUNTIFS(Trades!$A$2:$A$2161,A26,Trades!$B$2:$B$2161,B26,Trades!$M$2:$M$2161,1) -> 198 | F26: =IF(D26=0,"",E26/D26) -> 0.57894737 | G26: =SUMIFS(Trades!$K$2:$K$2161,Trades!$A$2:$A$2161,A26,Trades!$B$2:$B$2161,B26) -> 4262195 | H26: =SUMIFS(Trades!$K$2:$K$2161,Trades!$A$2:$A$2161,A26,Trades!$B$2:$B$2161,B26,Trades!$E$2:$E$2161,">="&DATE(2025,1,1),Trades!$E$2:$E$2161,"<"&DATE(2026,1,1)) -> 3134388 | I26: =SUMIFS(Trades!$K$2:$K$2161,Trades!$A$2:$A$2161,A26,Trades!$B$2:$B$2161,B26,Trades!$E$2:$E$2161,">="&DATE(2026,1,1)) -> 1127807 | J26: =IFERROR(AVERAGEIFS(Trades!$K$2:$K$2161,Trades!$A$2:$A$2161,A26,Trades!$B$2:$B$2161,B26,Trades!$K$2:$K$2161,">0"),0) -> 77768.5 | K26: =IFERROR(AVERAGEIFS(Trades!$K$2:$K$2161,Trades!$A$2:$A$2161,A26,Trades!$B$2:$B$2161,B26,Trades!$K$2:$K$2161,"<=0"),0) -> -77333.111 | L26: =IFERROR(SUMIFS(Trades!$K$2:$K$2161,Trades!$A$2:$A$2161,A26,Trades!$B$2:$B$2161,B26,Trades!$K$2:$K$2161,">0")/-SUMIFS(Trades!$K$2:$K$2161,Trades!$A$2:$A$2161,A26,Trades!$B$2:$B$2161,B26,Trades!$K$2:$K$2161,"<=0"),"no losses") -> 1.3827413 | M26: =_xlfn.MINIFS(Trades!$P$2:$P$2161,Trades!$A$2:$A$2161,A26,Trades!$B$2:$B$2161,B26) -> -2510915 | N26: =IFERROR(COUNTIF('Gold Monthly'!AF$5:AF$25,">0")/COUNTIF('Gold Monthly'!AD$5:AD$25,">0"),"") -> 0.71428571 | O26: =MAX('Gold Monthly'!AF$5:AF$25) -> 1578462 | P26: =MIN('Gold Monthly'!AF$5:AF$25) -> -1841983 | Q26: =D26/COUNT('Gold Monthly'!$A$5:$A$25) -> 16.285714
A27: GOLD | B27: Q1 | C27: 5m: 1h filter, lock 0.15R@0.3R, re-entry 120 | D27: =COUNTIFS(Trades!$A$2:$A$2161,A27,Trades!$B$2:$B$2161,B27) -> 344 | E27: =COUNTIFS(Trades!$A$2:$A$2161,A27,Trades!$B$2:$B$2161,B27,Trades!$M$2:$M$2161,1) -> 247 | F27: =IF(D27=0,"",E27/D27) -> 0.71802326 | G27: =SUMIFS(Trades!$K$2:$K$2161,Trades!$A$2:$A$2161,A27,Trades!$B$2:$B$2161,B27) -> 4366899 | H27: =SUMIFS(Trades!$K$2:$K$2161,Trades!$A$2:$A$2161,A27,Trades!$B$2:$B$2161,B27,Trades!$E$2:$E$2161,">="&DATE(2025,1,1),Trades!$E$2:$E$2161,"<"&DATE(2026,1,1)) -> 2494829 | I27: =SUMIFS(Trades!$K$2:$K$2161,Trades!$A$2:$A$2161,A27,Trades!$B$2:$B$2161,B27,Trades!$E$2:$E$2161,">="&DATE(2026,1,1)) -> 1872070 | J27: =IFERROR(AVERAGEIFS(Trades!$K$2:$K$2161,Trades!$A$2:$A$2161,A27,Trades!$B$2:$B$2161,B27,Trades!$K$2:$K$2161,">0"),0) -> 49716.174 | K27: =IFERROR(AVERAGEIFS(Trades!$K$2:$K$2161,Trades!$A$2:$A$2161,A27,Trades!$B$2:$B$2161,B27,Trades!$K$2:$K$2161,"<=0"),0) -> -81577.278 | L27: =IFERROR(SUMIFS(Trades!$K$2:$K$2161,Trades!$A$2:$A$2161,A27,Trades!$B$2:$B$2161,B27,Trades!$K$2:$K$2161,">0")/-SUMIFS(Trades!$K$2:$K$2161,Trades!$A$2:$A$2161,A27,Trades!$B$2:$B$2161,B27,Trades!$K$2:$K$2161,"<=0"),"no losses") -> 1.5518642 | M27: =_xlfn.MINIFS(Trades!$P$2:$P$2161,Trades!$A$2:$A$2161,A27,Trades!$B$2:$B$2161,B27) -> -1088229 | N27: =IFERROR(COUNTIF('Gold Monthly'!AJ$5:AJ$25,">0")/COUNTIF('Gold Monthly'!AH$5:AH$25,">0"),"") -> 0.6 | O27: =MAX('Gold Monthly'!AJ$5:AJ$25) -> 1851756 | P27: =MIN('Gold Monthly'!AJ$5:AJ$25) -> -562167 | Q27: =D27/COUNT('Gold Monthly'!$A$5:$A$25) -> 16.380952
A29: Highlighted rows = recommended setup (Day filter + profit lock). W8C was chosen after seeing results and rests on 16-18 trades. T6/T7/U1/U9 trade more often at a lower win rate. For 10+ trades a month with a high win rate: Q1 on Silver.

Sheet Trades
A1: Metal | B1: Strategy | C1: Side | D1: Entry time | E1: Exit time | F1: Exit month | G1: Entry price | H1: Exit reason | I1: Net points / lot (after costs) | J1: Lots | K1: Net P&L (₹) | L1: R multiple | M1: Win (1/0) | N1: Cumulative P&L (₹) | O1: Peak (₹) | P1: Drawdown (₹)
A2: SILVER | B2: V0 | C2: LONG | D2: 45663.708 | E2: 45680.792 | F2: =DATE(YEAR(E2),MONTH(E2),1) -> 45658 | G2: 129941 | H2: flip | I2: -502.14 | J2: =Summary!$B$4 -> 1 | K2: =I2*J2*IF(A2="SILVER",Summary!$B$5,Summary!$B$6) -> -15064.2 | L2: -0.175 | M2: =IF(K2>0,1,0) -> 0 | N2: =SUMIFS(K$2:K2,A$2:A2,A2,B$2:B2,B2) -> -15064.2 | O2: =MAX(0,_xlfn.MAXIFS(N$2:N2,A$2:A2,A2,B$2:B2,B2)) -> 0 | P2: =N2-O2 -> -15064.2
A3: SILVER | B3: V0 | C3: SHORT | D3: 45680.792 | E3: 45687.542 | F3: =DATE(YEAR(E3),MONTH(E3),1) -> 45658 | G3: 129467 | H3: flip | I3: -2145.3 | J3: =Summary!$B$4 -> 1 | K3: =I3*J3*IF(A3="SILVER",Summary!$B$5,Summary!$B$6) -> -64359 | L3: -0.895 | M3: =IF(K3>0,1,0) -> 0 | N3: =SUMIFS(K$2:K3,A$2:A3,A3,B$2:B3,B3) -> -79423.2 | O3: =MAX(0,_xlfn.MAXIFS(N$2:N3,A$2:A3,A3,B$2:B3,B3)) -> 0 | P3: =N3-O3 -> -79423.2
A4: SILVER | B4: V0 | C4: LONG | D4: 45687.542 | E4: 45699.792 | F4: =DATE(YEAR(E4),MONTH(E4),1) -> 45689 | G4: 131584 | H4: flip | I4: 730.41 | J4: =Summary!$B$4 -> 1 | K4: =I4*J4*IF(A4="SILVER",Summary!$B$5,Summary!$B$6) -> 21912.3 | L4: 0.309 | M4: =IF(K4>0,1,0) -> 1 | N4: =SUMIFS(K$2:K4,A$2:A4,A4,B$2:B4,B4) -> -57510.9 | O4: =MAX(0,_xlfn.MAXIFS(N$2:N4,A$2:A4,A4,B$2:B4,B4)) -> 0 | P4: =N4-O4 -> -57510.9
A5: SILVER | B5: V0 | C5: SHORT | D5: 45699.792 | E5: 45702.417 | F5: =DATE(YEAR(E5),MONTH(E5),1) -> 45689 | G5: 132343 | H5: flip | I5: -3073.97 | J5: =Summary!$B$4 -> 1 | K5: =I5*J5*IF(A5="SILVER",Summary!$B$5,Summary!$B$6) -> -92219.1 | L5: -1.128 | M5: =IF(K5>0,1,0) -> 0 | N5: =SUMIFS(K$2:K5,A$2:A5,A5,B$2:B5,B5) -> -149730 | O5: =MAX(0,_xlfn.MAXIFS(N$2:N5,A$2:A5,A5,B$2:B5,B5)) -> 0 | P5: =N5-O5 -> -149730
A6: SILVER | B6: V0 | C6: LONG | D6: 45702.417 | E6: 45702.917 | F6: =DATE(YEAR(E6),MONTH(E6),1) -> 45689 | G6: 135388 | H6: flip | I6: -785.2 | J6: =Summary!$B$4 -> 1 | K6: =I6*J6*IF(A6="SILVER",Summary!$B$5,Summary!$B$6) -> -23556 | L6: -0.286 | M6: =IF(K6>0,1,0) -> 0 | N6: =SUMIFS(K$2:K6,A$2:A6,A6,B$2:B6,B6) -> -173286 | O6: =MAX(0,_xlfn.MAXIFS(N$2:N6,A$2:A6,A6,B$2:B6,B6)) -> 0 | P6: =N6-O6 -> -173286
A7: SILVER | B7: V0 | C7: SHORT | D7: 45702.917 | E7: 45721.463 | F7: =DATE(YEAR(E7),MONTH(E7),1) -> 45717 | G7: 134632 | H7: flip | I7: 430.92 | J7: =Summary!$B$4 -> 1 | K7: =I7*J7*IF(A7="SILVER",Summary!$B$5,Summary!$B$6) -> 12927.6 | L7: 0.136 | M7: =IF(K7>0,1,0) -> 1 | N7: =SUMIFS(K$2:K7,A$2:A7,A7,B$2:B7,B7) -> -160358.4 | O7: =MAX(0,_xlfn.MAXIFS(N$2:N7,A$2:A7,A7,B$2:B7,B7)) -> 0 | P7: =N7-O7 -> -160358.4
A8: SILVER | B8: V0 | C8: LONG | D8: 45721.463 | E8: 45736.667 | F8: =DATE(YEAR(E8),MONTH(E8),1) -> 45717 | G8: 134172 | H8: flip | I8: 1719.77 | J8: =Summary!$B$4 -> 1 | K8: =I8*J8*IF(A8="SILVER",Summary!$B$5,Summary!$B$6) -> 51593.1 | L8: 0.885 | M8: =IF(K8>0,1,0) -> 1 | N8: =SUMIFS(K$2:K8,A$2:A8,A8,B$2:B8,B8) -> -108765.3 | O8: =MAX(0,_xlfn.MAXIFS(N$2:N8,A$2:A8,A8,B$2:B8,B8)) -> 0 | P8: =N8-O8 -> -108765.3
A9: SILVER | B9: V0 | C9: SHORT | D9: 45736.667 | E9: 45742.5 | F9: =DATE(YEAR(E9),MONTH(E9),1) -> 45717 | G9: 135951 | H9: flip | I9: -732.87 | J9: =Summary!$B$4 -> 1 | K9: =I9*J9*IF(A9="SILVER",Summary!$B$5,Summary!$B$6) -> -21986.1 | L9: -0.237 | M9: =IF(K9>0,1,0) -> 0 | N9: =SUMIFS(K$2:K9,A$2:A9,A9,B$2:B9,B9) -> -130751.4 | O9: =MAX(0,_xlfn.MAXIFS(N$2:N9,A$2:A9,A9,B$2:B9,B9)) -> 0 | P9: =N9-O9 -> -130751.4
A10: SILVER | B10: V0 | C10: LONG | D10: 45742.5 | E10: 45748.917 | F10: =DATE(YEAR(E10),MONTH(E10),1) -> 45748 | G10: 136654 | H10: flip | I10: -386.89 | J10: =Summary!$B$4 -> 1 | K10: =I10*J10*IF(A10="SILVER",Summary!$B$5,Summary!$B$6) -> -11606.7 | L10: -0.176 | M10: =IF(K10>0,1,0) -> 0 | N10: =SUMIFS(K$2:K10,A$2:A10,A10,B$2:B10,B10) -> -142358.1 | O10: =MAX(0,_xlfn.MAXIFS(N$2:N10,A$2:A10,A10,B$2:B10,B10)) -> 0 | P10: =N10-O10 -> -142358.1
A11: SILVER | B11: V0 | C11: SHORT | D11: 45748.917 | E11: 45758.583 | F11: =DATE(YEAR(E11),MONTH(E11),1) -> 45748 | G11: 136297 | H11: flip | I11: 6488.79 | J11: =Summary!$B$4 -> 1 | K11: =I11*J11*IF(A11="SILVER",Summary!$B$5,Summary!$B$6) -> 194663.7 | L11: 2.033 | M11: =IF(K11>0,1,0) -> 1 | N11: =SUMIFS(K$2:K11,A$2:A11,A11,B$2:B11,B11) -> 52305.6 | O11: =MAX(0,_xlfn.MAXIFS(N$2:N11,A$2:A11,A11,B$2:B11,B11)) -> 52305.6 | P11: =N11-O11 -> 0
A12: SILVER | B12: V0 | C12: LONG | D12: 45758.583 | E12: 45777.583 | F12: =DATE(YEAR(E12),MONTH(E12),1) -> 45748 | G12: 129779 | H12: flip | I12: 1392.31 | J12: =Summary!$B$4 -> 1 | K12: =I12*J12*IF(A12="SILVER",Summary!$B$5,Summary!$B$6) -> 41769.3 | L12: 0.319 | M12: =IF(K12>0,1,0) -> 1 | N12: =SUMIFS(K$2:K12,A$2:A12,A12,B$2:B12,B12) -> 94074.9 | O12: =MAX(0,_xlfn.MAXIFS(N$2:N12,A$2:A12,A12,B$2:B12,B12)) -> 94074.9 | P12: =N12-O12 -> 0
A13: SILVER | B13: V0 | C13: SHORT | D13: 45777.583 | E13: 45790.583 | F13: =DATE(YEAR(E13),MONTH(E13),1) -> 45778 | G13: 131200 | H13: flip | I13: -1298.69 | J13: =Summary!$B$4 -> 1 | K13: =I13*J13*IF(A13="SILVER",Summary!$B$5,Summary!$B$6) -> -38960.7 | L13: -0.351 | M13: =IF(K13>0,1,0) -> 0 | N13: =SUMIFS(K$2:K13,A$2:A13,A13,B$2:B13,B13) -> 55114.2 | O13: =MAX(0,_xlfn.MAXIFS(N$2:N13,A$2:A13,A13,B$2:B13,B13)) -> 94074.9 | P13: =N13-O13 -> -38960.7
... A2161: GOLD | B2161: Q1 | C2161: LONG | D2161: 46288.375 | E2161: 46288.381 | F2161: =DATE(YEAR(E2161),MONTH(E2161),1) -> 46266 | G2161: 152575 | H2161: stop | I2161: 17.03 | J2161: =Summary!$B$4 -> 1 | K2161: =I2161*J2161*IF(A2161="SILVER",Summary!$B$5,Summary!$B$6) -> 1703 | L2161: 0.044 | M2161: =IF(K2161>0,1,0) -> 1 | N2161: =SUMIFS(K$2:K2161,A$2:A2161,A2161,B$2:B2161,B2161) -> 4366899 | O2161: =MAX(0,_xlfn.MAXIFS(N$2:N2161,A$2:A2161,A2161,B$2:B2161,B2161)) -> 5409495 | P2161: =N2161-O2161 -> -1042596

Sheet Silver Monthly
A1: Silver - monthly backtest (P&L booked in the month a trade closes)
A2: All figures are formulas over the Trades sheet; lot size comes from Summary!B4.
A3: Month | B3: V0: Real Buy/Sell, always in | F3: V1: Day filter | J3: W8: Day filter + profit lock | N3: W8C: Day + lock + 1-bar confirm | R3: T6: W8, faster band x3/x4 (1h) | V3: T7: W8 on 30m + trend re-entry | Z3: U1: W8 on 15m chart | AD3: U9: W8 on 5m chart | AH3: Q1: 5m: 1h filter, lock 0.15R@0.3R, re-entry 120
B4: Trades | C4: Win % | D4: Net P&L (₹) | E4: Cumulative (₹) | F4: Trades | G4: Win % | H4: Net P&L (₹) | I4: Cumulative (₹) | J4: Trades | K4: Win % | L4: Net P&L (₹) | M4: Cumulative (₹) | N4: Trades | O4: Win % | P4: Net P&L (₹) | Q4: Cumulative (₹) | R4: Trades | S4: Win % | T4: Net P&L (₹) | U4: Cumulative (₹) | V4: Trades | W4: Win % | X4: Net P&L (₹) | Y4: Cumulative (₹) | Z4: Trades | AA4: Win % | AB4: Net P&L (₹) | AC4: Cumulative (₹) | AD4: Trades | AE4: Win % | AF4: Net P&L (₹) | AG4: Cumulative (₹) | AH4: Trades | AI4: Win % | AJ4: Net P&L (₹) | AK4: Cumulative (₹)
A5: 45658 | B5: =COUNTIFS(Trades!$A$2:$A$2161,"SILVER",Trades!$B$2:$B$2161,"V0",Trades!$F$2:$F$2161,$A5) -> 2 | C5: =IF(B5=0,"",COUNTIFS(Trades!$A$2:$A$2161,"SILVER",Trades!$B$2:$B$2161,"V0",Trades!$F$2:$F$2161,$A5,Trades!$M$2:$M$2161,1)/B5) -> 0 | D5: =SUMIFS(Trades!$K$2:$K$2161,Trades!$A$2:$A$2161,"SILVER",Trades!$B$2:$B$2161,"V0",Trades!$F$2:$F$2161,$A5) -> -79423.2 | E5: =D5 -> -79423.2 | F5: =COUNTIFS(Trades!$A$2:$A$2161,"SILVER",Trades!$B$2:$B$2161,"V1",Trades!$F$2:$F$2161,$A5) -> 0 | G5: =IF(F5=0,"",COUNTIFS(Trades!$A$2:$A$2161,"SILVER",Trades!$B$2:$B$2161,"V1",Trades!$F$2:$F$2161,$A5,Trades!$M$2:$M$2161,1)/F5) | H5: =SUMIFS(Trades!$K$2:$K$2161,Trades!$A$2:$A$2161,"SILVER",Trades!$B$2:$B$2161,"V1",Trades!$F$2:$F$2161,$A5) -> 0 | I5: =H5 -> 0 | J5: =COUNTIFS(Trades!$A$2:$A$2161,"SILVER",Trades!$B$2:$B$2161,"W8",Trades!$F$2:$F$2161,$A5) -> 0 | K5: =IF(J5=0,"",COUNTIFS(Trades!$A$2:$A$2161,"SILVER",Trades!$B$2:$B$2161,"W8",Trades!$F$2:$F$2161,$A5,Trades!$M$2:$M$2161,1)/J5) | L5: =SUMIFS(Trades!$K$2:$K$2161,Trades!$A$2:$A$2161,"SILVER",Trades!$B$2:$B$2161,"W8",Trades!$F$2:$F$2161,$A5) -> 0 | M5: =L5 -> 0 | N5: =COUNTIFS(Trades!$A$2:$A$2161,"SILVER",Trades!$B$2:$B$2161,"W8C",Trades!$F$2:$F$2161,$A5) -> 0 | O5: =IF(N5=0,"",COUNTIFS(Trades!$A$2:$A$2161,"SILVER",Trades!$B$2:$B$2161,"W8C",Trades!$F$2:$F$2161,$A5,Trades!$M$2:$M$2161,1)/N5) | P5: =SUMIFS(Trades!$K$2:$K$2161,Trades!$A$2:$A$2161,"SILVER",Trades!$B$2:$B$2161,"W8C",Trades!$F$2:$F$2161,$A5) -> 0 | Q5: =P5 -> 0 | R5: =COUNTIFS(Trades!$A$2:$A$2161,"SILVER",Trades!$B$2:$B$2161,"T6",Trades!$F$2:$F$2161,$A5) -> 0 | S5: =IF(R5=0,"",COUNTIFS(Trades!$A$2:$A$2161,"SILVER",Trades!$B$2:$B$2161,"T6",Trades!$F$2:$F$2161,$A5,Trades!$M$2:$M$2161,1)/R5) | T5: =SUMIFS(Trades!$K$2:$K$2161,Trades!$A$2:$A$2161,"SILVER",Trades!$B$2:$B$2161,"T6",Trades!$F$2:$F$2161,$A5) -> 0 | U5: =T5 -> 0 | V5: =COUNTIFS(Trades!$A$2:$A$2161,"SILVER",Trades!$B$2:$B$2161,"T7",Trades!$F$2:$F$2161,$A5) -> 0 | W5: =IF(V5=0,"",COUNTIFS(Trades!$A$2:$A$2161,"SILVER",Trades!$B$2:$B$2161,"T7",Trades!$F$2:$F$2161,$A5,Trades!$M$2:$M$2161,1)/V5) | X5: =SUMIFS(Trades!$K$2:$K$2161,Trades!$A$2:$A$2161,"SILVER",Trades!$B$2:$B$2161,"T7",Trades!$F$2:$F$2161,$A5) -> 0 | Y5: =X5 -> 0 | Z5: =COUNTIFS(Trades!$A$2:$A$2161,"SILVER",Trades!$B$2:$B$2161,"U1",Trades!$F$2:$F$2161,$A5) -> 0 | AA5: =IF(Z5=0,"",COUNTIFS(Trades!$A$2:$A$2161,"SILVER",Trades!$B$2:$B$2161,"U1",Trades!$F$2:$F$2161,$A5,Trades!$M$2:$M$2161,1)/Z5) | AB5: =SUMIFS(Trades!$K$2:$K$2161,Trades!$A$2:$A$2161,"SILVER",Trades!$B$2:$B$2161,"U1",Trades!$F$2:$F$2161,$A5) -> 0 | AC5: =AB5 -> 0 | AD5: =COUNTIFS(Trades!$A$2:$A$2161,"SILVER",Trades!$B$2:$B$2161,"U9",Trades!$F$2:$F$2161,$A5) -> 1 | AE5: =IF(AD5=0,"",COUNTIFS(Trades!$A$2:$A$2161,"SILVER",Trades!$B$2:$B$2161,"U9",Trades!$F$2:$F$2161,$A5,Trades!$M$2:$M$2161,1)/AD5) -> 1 | AF5: =SUMIFS(Trades!$K$2:$K$2161,Trades!$A$2:$A$2161,"SILVER",Trades!$B$2:$B$2161,"U9",Trades!$F$2:$F$2161,$A5) -> 702 | AG5: =AF5 -> 702 | AH5: =COUNTIFS(Trades!$A$2:$A$2161,"SILVER",Trades!$B$2:$B$2161,"Q1",Trades!$F$2:$F$2161,$A5) -> 0 | AI5: =IF(AH5=0,"",COUNTIFS(Trades!$A$2:$A$2161,"SILVER",Trades!$B$2:$B$2161,"Q1",Trades!$F$2:$F$2161,$A5,Trades!$M$2:$M$2161,1)/AH5) | AJ5: =SUMIFS(Trades!$K$2:$K$2161,Trades!$A$2:$A$2161,"SILVER",Trades!$B$2:$B$2161,"Q1",Trades!$F$2:$F$2161,$A5) -> 0 | AK5: =AJ5 -> 0
A6: 45689 | B6: =COUNTIFS(Trades!$A$2:$A$2161,"SILVER",Trades!$B$2:$B$2161,"V0",Trades!$F$2:$F$2161,$A6) -> 3 | C6: =IF(B6=0,"",COUNTIFS(Trades!$A$2:$A$2161,"SILVER",Trades!$B$2:$B$2161,"V0",Trades!$F$2:$F$2161,$A6,Trades!$M$2:$M$2161,1)/B6) -> 0.33333333 | D6: =SUMIFS(Trades!$K$2:$K$2161,Trades!$A$2:$A$2161,"SILVER",Trades!$B$2:$B$2161,"V0",Trades!$F$2:$F$2161,$A6) -> -93862.8 | E6: =E5+D6 -> -173286 | F6: =COUNTIFS(Trades!$A$2:$A$2161,"SILVER",Trades!$B$2:$B$2161,"V1",Trades!$F$2:$F$2161,$A6) -> 1 | G6: =IF(F6=0,"",COUNTIFS(Trades!$A$2:$A$2161,"SILVER",Trades!$B$2:$B$2161,"V1",Trades!$F$2:$F$2161,$A6,Trades!$M$2:$M$2161,1)/F6) -> 0 | H6: =SUMIFS(Trades!$K$2:$K$2161,Trades!$A$2:$A$2161,"SILVER",Trades!$B$2:$B$2161,"V1",Trades!$F$2:$F$2161,$A6) -> -92219.1 | I6: =I5+H6 -> -92219.1 | J6: =COUNTIFS(Trades!$A$2:$A$2161,"SILVER",Trades!$B$2:$B$2161,"W8",Trades!$F$2:$F$2161,$A6) -> 1 | K6: =IF(J6=0,"",COUNTIFS(Trades!$A$2:$A$2161,"SILVER",Trades!$B$2:$B$2161,"W8",Trades!$F$2:$F$2161,$A6,Trades!$M$2:$M$2161,1)/J6) -> 0 | L6: =SUMIFS(Trades!$K$2:$K$2161,Trades!$A$2:$A$2161,"SILVER",Trades!$B$2:$B$2161,"W8",Trades!$F$2:$F$2161,$A6) -> -92219.1 | M6: =M5+L6 -> -92219.1 | N6: =COUNTIFS(Trades!$A$2:$A$2161,"SILVER",Trades!$B$2:$B$2161,"W8C",Trades!$F$2:$F$2161,$A6) -> 0 | O6: =IF(N6=0,"",COUNTIFS(Trades!$A$2:$A$2161,"SILVER",Trades!$B$2:$B$2161,"W8C",Trades!$F$2:$F$2161,$A6,Trades!$M$2:$M$2161,1)/N6) | P6: =SUMIFS(Trades!$K$2:$K$2161,Trades!$A$2:$A$2161,"SILVER",Trades!$B$2:$B$2161,"W8C",Trades!$F$2:$F$2161,$A6) -> 0 | Q6: =Q5+P6 -> 0 | R6: =COUNTIFS(Trades!$A$2:$A$2161,"SILVER",Trades!$B$2:$B$2161,"T6",Trades!$F$2:$F$2161,$A6) -> 3 | S6: =IF(R6=0,"",COUNTIFS(Trades!$A$2:$A$2161,"SILVER",Trades!$B$2:$B$2161,"T6",Trades!$F$2:$F$2161,$A6,Trades!$M$2:$M$2161,1)/R6) -> 0.66666667 | T6: =SUMIFS(Trades!$K$2:$K$2161,Trades!$A$2:$A$2161,"SILVER",Trades!$B$2:$B$2161,"T6",Trades!$F$2:$F$2161,$A6) -> -28711.2 | U6: =U5+T6 -> -28711.2 | V6: =COUNTIFS(Trades!$A$2:$A$2161,"SILVER",Trades!$B$2:$B$2161,"T7",Trades!$F$2:$F$2161,$A6) -> 4 | W6: =IF(V6=0,"",COUNTIFS(Trades!$A$2:$A$2161,"SILVER",Trades!$B$2:$B$2161,"T7",Trades!$F$2:$F$2161,$A6,Trades!$M$2:$M$2161,1)/V6) -> 1 | X6: =SUMIFS(Trades!$K$2:$K$2161,Trades!$A$2:$A$2161,"SILVER",Trades!$B$2:$B$2161,"T7",Trades!$F$2:$F$2161,$A6) -> 19050.3 | Y6: =Y5+X6 -> 19050.3 | Z6: =COUNTIFS(Trades!$A$2:$A$2161,"SILVER",Trades!$B$2:$B$2161,"U1",Trades!$F$2:$F$2161,$A6) -> 5 | AA6: =IF(Z6=0,"",COUNTIFS(Trades!$A$2:$A$2161,"SILVER",Trades!$B$2:$B$2161,"U1",Trades!$F$2:$F$2161,$A6,Trades!$M$2:$M$2161,1)/Z6) -> 0.6 | AB6: =SUMIFS(Trades!$K$2:$K$2161,Trades!$A$2:$A$2161,"SILVER",Trades!$B$2:$B$2161,"U1",Trades!$F$2:$F$2161,$A6) -> 8373.3 | AC6: =AC5+AB6 -> 8373.3 | AD6: =COUNTIFS(Trades!$A$2:$A$2161,"SILVER",Trades!$B$2:$B$2161,"U9",Trades!$F$2:$F$2161,$A6) -> 20 | AE6: =IF(AD6=0,"",COUNTIFS(Trades!$A$2:$A$2161,"SILVER",Trades!$B$2:$B$2161,"U9",Trades!$F$2:$F$2161,$A6,Trades!$M$2:$M$2161,1)/AD6) -> 0.75 | AF6: =SUMIFS(Trades!$K$2:$K$2161,Trades!$A$2:$A$2161,"SILVER",Trades!$B$2:$B$2161,"U9",Trades!$F$2:$F$2161,$A6) -> -38111.7 | AG6: =AG5+AF6 -> -37409.7 | AH6: =COUNTIFS(Trades!$A$2:$A$2161,"SILVER",Trades!$B$2:$B$2161,"Q1",Trades!$F$2:$F$2161,$A6) -> 24 | AI6: =IF(AH6=0,"",COUNTIFS(Trades!$A$2:$A$2161,"SILVER",Trades!$B$2:$B$2161,"Q1",Trades!$F$2:$F$2161,$A6,Trades!$M$2:$M$2161,1)/AH6) -> 0.58333333 | AJ6: =SUMIFS(Trades!$K$2:$K$2161,Trades!$A$2:$A$2161,"SILVER",Trades!$B$2:$B$2161,"Q1",Trades!$F$2:$F$2161,$A6) -> -134557.2 | AK6: =AK5+AJ6 -> -134557.2
A7: 45717 | B7: =COUNTIFS(Trades!$A$2:$A$2161,"SILVER",Trades!$B$2:$B$2161,"V0",Trades!$F$2:$F$2161,$A7) -> 3 | C7: =IF(B7=0,"",COUNTIFS(Trades!$A$2:$A$2161,"SILVER",Trades!$B$2:$B$2161,"V0",Trades!$F$2:$F$2161,$A7,Trades!$M$2:$M$2161,1)/B7) -> 0.66666667 | D7: =SUMIFS(Trades!$K$2:$K$2161,Trades!$A$2:$A$2161,"SILVER",Trades!$B$2:$B$2161,"V0",Trades!$F$2:$F$2161,$A7) -> 42534.6 | E7: =E6+D7 -> -130751.4 | F7: =COUNTIFS(Trades!$A$2:$A$2161,"SILVER",Trades!$B$2:$B$2161,"V1",Trades!$F$2:$F$2161,$A7) -> 2 | G7: =IF(F7=0,"",COUNTIFS(Trades!$A$2:$A$2161,"SILVER",Trades!$B$2:$B$2161,"V1",Trades!$F$2:$F$2161,$A7,Trades!$M$2:$M$2161,1)/F7) -> 0.5 | H7: =SUMIFS(Trades!$K$2:$K$2161,Trades!$A$2:$A$2161,"SILVER",Trades!$B$2:$B$2161,"V1",Trades!$F$2:$F$2161,$A7) -> -9058.5 | I7: =I6+H7 -> -101277.6 | J7: =COUNTIFS(Trades!$A$2:$A$2161,"SILVER",Trades!$B$2:$B$2161,"W8",Trades!$F$2:$F$2161,$A7) -> 2 | K7: =IF(J7=0,"",COUNTIFS(Trades!$A$2:$A$2161,"SILVER",Trades!$B$2:$B$2161,"W8",Trades!$F$2:$F$2161,$A7,Trades!$M$2:$M$2161,1)/J7) -> 1 | L7: =SUMIFS(Trades!$K$2:$K$2161,Trades!$A$2:$A$2161,"SILVER",Trades!$B$2:$B$2161,"W8",Trades!$F$2:$F$2161,$A7) -> 21321.3 | M7: =M6+L7 -> -70897.8 | N7: =COUNTIFS(Trades!$A$2:$A$2161,"SILVER",Trades!$B$2:$B$2161,"W8C",Trades!$F$2:$F$2161,$A7) -> 2 | O7: =IF(N7=0,"",COUNTIFS(Trades!$A$2:$A$2161,"SILVER",Trades!$B$2:$B$2161,"W8C",Trades!$F$2:$F$2161,$A7,Trades!$M$2:$M$2161,1)/N7) -> 1 | P7: =SUMIFS(Trades!$K$2:$K$2161,Trades!$A$2:$A$2161,"SILVER",Trades!$B$2:$B$2161,"W8C",Trades!$F$2:$F$2161,$A7) -> 15062.4 | Q7: =Q6+P7 -> 15062.4 | R7: =COUNTIFS(Trades!$A$2:$A$2161,"SILVER",Trades!$B$2:$B$2161,"T6",Trades!$F$2:$F$2161,$A7) -> 3 | S7: =IF(R7=0,"",COUNTIFS(Trades!$A$2:$A$2161,"SILVER",Trades!$B$2:$B$2161,"T6",Trades!$F$2:$F$2161,$A7,Trades!$M$2:$M$2161,1)/R7) -> 1 | T7: =SUMIFS(Trades!$K$2:$K$2161,Trades!$A$2:$A$2161,"SILVER",Trades!$B$2:$B$2161,"T6",Trades!$F$2:$F$2161,$A7) -> 57892.2 | U7: =U6+T7 -> 29181 | V7: =COUNTIFS(Trades!$A$2:$A$2161,"SILVER",Trades!$B$2:$B$2161,"T7",Trades!$F$2:$F$2161,$A7) -> 4 | W7: =IF(V7=0,"",COUNTIFS(Trades!$A$2:$A$2161,"SILVER",Trades!$B$2:$B$2161,"T7",Trades!$F$2:$F$2161,$A7,Trades!$M$2:$M$2161,1)/V7) -> 0.5 | X7: =SUMIFS(Trades!$K$2:$K$2161,Trades!$A$2:$A$2161,"SILVER",Trades!$B$2:$B$2161,"T7",Trades!$F$2:$F$2161,$A7) -> -60510.6 | Y7: =Y6+X7 -> -41460.3 | Z7: =COUNTIFS(Trades!$A$2:$A$2161,"SILVER",Trades!$B$2:$B$2161,"U1",Trades!$F$2:$F$2161,$A7) -> 6 | AA7: =IF(Z7=0,"",COUNTIFS(Trades!$A$2:$A$2161,"SILVER",Trades!$B$2:$B$2161,"U1",Trades!$F$2:$F$2161,$A7,Trades!$M$2:$M$2161,1)/Z7) -> 0.5 | AB7: =SUMIFS(Trades!$K$2:$K$2161,Trades!$A$2:$A$2161,"SILVER",Trades!$B$2:$B$2161,"U1",Trades!$F$2:$F$2161,$A7) -> -34608.3 | AC7: =AC6+AB7 -> -26235 | AD7: =COUNTIFS(Trades!$A$2:$A$2161,"SILVER",Trades!$B$2:$B$2161,"U9",Trades!$F$2:$F$2161,$A7) -> 16 | AE7: =IF(AD7=0,"",COUNTIFS(Trades!$A$2:$A$2161,"SILVER",Trades!$B$2:$B$2161,"U9",Trades!$F$2:$F$2161,$A7,Trades!$M$2:$M$2161,1)/AD7) -> 0.5 | AF7: =SUMIFS(Trades!$K$2:$K$2161,Trades!$A$2:$A$2161,"SILVER",Trades!$B$2:$B$2161,"U9",Trades!$F$2:$F$2161,$A7) -> -130689 | AG7: =AG6+AF7 -> -168098.7 | AH7: =COUNTIFS(Trades!$A$2:$A$2161,"SILVER",Trades!$B$2:$B$2161,"Q1",Trades!$F$2:$F$2161,$A7) -> 9 | AI7: =IF(AH7=0,"",COUNTIFS(Trades!$A$2:$A$2161,"SILVER",Trades!$B$2:$B$2161,"Q1",Trades!$F$2:$F$2161,$A7,Trades!$M$2:$M$2161,1)/AH7) -> 0.55555556 | AJ7: =SUMIFS(Trades!$K$2:$K$2161,Trades!$A$2:$A$2161,"SILVER",Trades!$B$2:$B$2161,"Q1",Trades!$F$2:$F$2161,$A7) -> -76943.4 | AK7: =AK6+AJ7 -> -211500.6
A8: 45748 | B8: =COUNTIFS(Trades!$A$2:$A$2161,"SILVER",Trades!$B$2:$B$2161,"V0",Trades!$F$2:$F$2161,$A8) -> 3 | C8: =IF(B8=0,"",COUNTIFS(Trades!$A$2:$A$2161,"SILVER",Trades!$B$2:$B$2161,"V0",Trades!$F$2:$F$2161,$A8,Trades!$M$2:$M$2161,1)/B8) -> 0.66666667 | D8: =SUMIFS(Trades!$K$2:$K$2161,Trades!$A$2:$A$2161,"SILVER",Trades!$B$2:$B$2161,"V0",Trades!$F$2:$F$2161,$A8) -> 224826.3 | E8: =E7+D8 -> 94074.9 | F8: =COUNTIFS(Trades!$A$2:$A$2161,"SILVER",Trades!$B$2:$B$2161,"V1",Trades!$F$2:$F$2161,$A8) -> 1 | G8: =IF(F8=0,"",COUNTIFS(Trades!$A$2:$A$2161,"SILVER",Trades!$B$2:$B$2161,"V1",Trades!$F$2:$F$2161,$A8,Trades!$M$2:$M$2161,1)/F8) -> 1 | H8: =SUMIFS(Trades!$K$2:$K$2161,Trades!$A$2:$A$2161,"SILVER",Trades!$B$2:$B$2161,"V1",Trades!$F$2:$F$2161,$A8) -> 194663.7 | I8: =I7+H8 -> 93386.1 | J8: =COUNTIFS(Trades!$A$2:$A$2161,"SILVER",Trades!$B$2:$B$2161,"W8",Trades!$F$2:$F$2161,$A8) -> 1 | K8: =IF(J8=0,"",COUNTIFS(Trades!$A$2:$A$2161,"SILVER",Trades!$B$2:$B$2161,"W8",Trades!$F$2:$F$2161,$A8,Trades!$M$2:$M$2161,1)/J8) -> 1 | L8: =SUMIFS(Trades!$K$2:$K$2161,Trades!$A$2:$A$2161,"SILVER",Trades!$B$2:$B$2161,"W8",Trades!$F$2:$F$2161,$A8) -> 194663.7 | M8: =M7+L8 -> 123765.9 | N8: =COUNTIFS(Trades!$A$2:$A$2161,"SILVER",Trades!$B$2:$B$2161,"W8C",Trades!$F$2:$F$2161,$A8) -> 0 | O8: =IF(N8=0,"",COUNTIFS(Trades!$A$2:$A$2161,"SILVER",Trades!$B$2:$B$2161,"W8C",Trades!$F$2:$F$2161,$A8,Trades!$M$2:$M$2161,1)/N8) | P8: =SUMIFS(Trades!$K$2:$K$2161,Trades!$A$2:$A$2161,"SILVER",Trades!$B$2:$B$2161,"W8C",Trades!$F$2:$F$2161,$A8) -> 0 | Q8: =Q7+P8 -> 15062.4 | R8: =COUNTIFS(Trades!$A$2:$A$2161,"SILVER",Trades!$B$2:$B$2161,"T6",Trades!$F$2:$F$2161,$A8) -> 2 | S8: =IF(R8=0,"",COUNTIFS(Trades!$A$2:$A$2161,"SILVER",Trades!$B$2:$B$2161,"T6",Trades!$F$2:$F$2161,$A8,Trades!$M$2:$M$2161,1)/R8) -> 0 | T8: =SUMIFS(Trades!$K$2:$K$2161,Trades!$A$2:$A$2161,"SILVER",Trades!$B$2:$B$2161,"T6",Trades!$F$2:$F$2161,$A8) -> -119112 | U8: =U7+T8 -> -89931 | V8: =COUNTIFS(Trades!$A$2:$A$2161,"SILVER",Trades!$B$2:$B$2161,"T7",Trades!$F$2:$F$2161,$A8) -> 3 | W8: =IF(V8=0,"",COUNTIFS(Trades!$A$2:$A$2161,"SILVER",Trades!$B$2:$B$2161,"T7",Trades!$F$2:$F$2161,$A8,Trades!$M$2:$M$2161,1)/V8) -> 0.33333333 | X8: =SUMIFS(Trades!$K$2:$K$2161,Trades!$A$2:$A$2161,"SILVER",Trades!$B$2:$B$2161,"T7",Trades!$F$2:$F$2161,$A8) -> 139572.9 | Y8: =Y7+X8 -> 98112.6 | Z8: =COUNTIFS(Trades!$A$2:$A$2161,"SILVER",Trades!$B$2:$B$2161,"U1",Trades!$F$2:$F$2161,$A8) -> 5 | AA8: =IF(Z8=0,"",COUNTIFS(Trades!$A$2:$A$2161,"SILVER",Trades!$B$2:$B$2161,"U1",Trades!$F$2:$F$2161,$A8,Trades!$M$2:$M$2161,1)/Z8) -> 0.6 | AB8: =SUMIFS(Trades!$K$2:$K$2161,Trades!$A$2:$A$2161,"SILVER",Trades!$B$2:$B$2161,"U1",Trades!$F$2:$F$2161,$A8) -> -19603.8 | AC8: =AC7+AB8 -> -45838.8 | AD8: =COUNTIFS(Trades!$A$2:$A$2161,"SILVER",Trades!$B$2:$B$2161,"U9",Trades!$F$2:$F$2161,$A8) -> 16 | AE8: =IF(AD8=0,"",COUNTIFS(Trades!$A$2:$A$2161,"SILVER",Trades!$B$2:$B$2161,"U9",Trades!$F$2:$F$2161,$A8,Trades!$M$2:$M$2161,1)/AD8) -> 0.5 | AF8: =SUMIFS(Trades!$K$2:$K$2161,Trades!$A$2:$A$2161,"SILVER",Trades!$B$2:$B$2161,"U9",Trades!$F$2:$F$2161,$A8) -> 274004.7 | AG8: =AG7+AF8 -> 105906 | AH8: =COUNTIFS(Trades!$A$2:$A$2161,"SILVER",Trades!$B$2:$B$2161,"Q1",Trades!$F$2:$F$2161,$A8) -> 7 | AI8: =IF(AH8=0,"",COUNTIFS(Trades!$A$2:$A$2161,"SILVER",Trades!$B$2:$B$2161,"Q1",Trades!$F$2:$F$2161,$A8,Trades!$M$2:$M$2161,1)/AH8) -> 0.85714286 | AJ8: =SUMIFS(Trades!$K$2:$K$2161,Trades!$A$2:$A$2161,"SILVER",Trades!$B$2:$B$2161,"Q1",Trades!$F$2:$F$2161,$A8) -> 285214.2 | AK8: =AK7+AJ8 -> 73713.6
A9: 45778 | B9: =COUNTIFS(Trades!$A$2:$A$2161,"SILVER",Trades!$B$2:$B$2161,"V0",Trades!$F$2:$F$2161,$A9) -> 4 | C9: =IF(B9=0,"",COUNTIFS(Trades!$A$2:$A$2161,"SILVER",Trades!$B$2:$B$2161,"V0",Trades!$F$2:$F$2161,$A9,Trades!$M$2:$M$2161,1)/B9) -> 0 | D9: =SUMIFS(Trades!$K$2:$K$2161,Trades!$A$2:$A$2161,"SILVER",Trades!$B$2:$B$2161,"V0",Trades!$F$2:$F$2161,$A9) -> -238361.4 | E9: =E8+D9 -> -144286.5 | F9: =COUNTIFS(Trades!$A$2:$A$2161,"SILVER",Trades!$B$2:$B$2161,"V1",Trades!$F$2:$F$2161,$A9) -> 2 | G9: =IF(F9=0,"",COUNTIFS(Trades!$A$2:$A$2161,"SILVER",Trades!$B$2:$B$2161,"V1",Trades!$F$2:$F$2161,$A9,Trades!$M$2:$M$2161,1)/F9) -> 0 | H9: =SUMIFS(Trades!$K$2:$K$2161,Trades!$A$2:$A$2161,"SILVER",Trades!$B$2:$B$2161,"V1",Trades!$F$2:$F$2161,$A9) -> -127134.3 | I9: =I8+H9 -> -33748.2 | J9: =COUNTIFS(Trades!$A$2:$A$2161,"SILVER",Trades!$B$2:$B$2161,"W8",Trades!$F$2:$F$2161,$A9) -> 2 | K9: =IF(J9=0,"",COUNTIFS(Trades!$A$2:$A$2161,"SILVER",Trades!$B$2:$B$2161,"W8",Trades!$F$2:$F$2161,$A9,Trades!$M$2:$M$2161,1)/J9) -> 0.5 | L9: =SUMIFS(Trades!$K$2:$K$2161,Trades!$A$2:$A$2161,"SILVER",Trades!$B$2:$B$2161,"W8",Trades!$F$2:$F$2161,$A9) -> -79947.9 | M9: =M8+L9 -> 43818 | N9: =COUNTIFS(Trades!$A$2:$A$2161,"SILVER",Trades!$B$2:$B$2161,"W8C",Trades!$F$2:$F$2161,$A9) -> 1 | O9: =IF(N9=0,"",COUNTIFS(Trades!$A$2:$A$2161,"SILVER",Trades!$B$2:$B$2161,"W8C",Trades!$F$2:$F$2161,$A9,Trades!$M$2:$M$2161,1)/N9) -> 1 | P9: =SUMIFS(Trades!$K$2:$K$2161,Trades!$A$2:$A$2161,"SILVER",Trades!$B$2:$B$2161,"W8C",Trades!$F$2:$F$2161,$A9) -> 7236 | Q9: =Q8+P9 -> 22298.4 | R9: =COUNTIFS(Trades!$A$2:$A$2161,"SILVER",Trades!$B$2:$B$2161,"T6",Trades!$F$2:$F$2161,$A9) -> 2 | S9: =IF(R9=0,"",COUNTIFS(Trades!$A$2:$A$2161,"SILVER",Trades!$B$2:$B$2161,"T6",Trades!$F$2:$F$2161,$A9,Trades!$M$2:$M$2161,1)/R9) -> 1 | T9: =SUMIFS(Trades!$K$2:$K$2161,Trades!$A$2:$A$2161,"SILVER",Trades!$B$2:$B$2161,"T6",Trades!$F$2:$F$2161,$A9) -> 31165.8 | U9: =U8+T9 -> -58765.2 | V9: =COUNTIFS(Trades!$A$2:$A$2161,"SILVER",Trades!$B$2:$B$2161,"T7",Trades!$F$2:$F$2161,$A9) -> 3 | W9: =IF(V9=0,"",COUNTIFS(Trades!$A$2:$A$2161,"SILVER",Trades!$B$2:$B$2161,"T7",Trades!$F$2:$F$2161,$A9,Trades!$M$2:$M$2161,1)/V9) -> 0.66666667 | X9: =SUMIFS(Trades!$K$2:$K$2161,Trades!$A$2:$A$2161,"SILVER",Trades!$B$2:$B$2161,"T7",Trades!$F$2:$F$2161,$A9) -> -46257.3 | Y9: =Y8+X9 -> 51855.3 | Z9: =COUNTIFS(Trades!$A$2:$A$2161,"SILVER",Trades!$B$2:$B$2161,"U1",Trades!$F$2:$F$2161,$A9) -> 9 | AA9: =IF(Z9=0,"",COUNTIFS(Trades!$A$2:$A$2161,"SILVER",Trades!$B$2:$B$2161,"U1",Trades!$F$2:$F$2161,$A9,Trades!$M$2:$M$2161,1)/Z9) -> 0.44444444 | AB9: =SUMIFS(Trades!$K$2:$K$2161,Trades!$A$2:$A$2161,"SILVER",Trades!$B$2:$B$2161,"U1",Trades!$F$2:$F$2161,$A9) -> -87085.8 | AC9: =AC8+AB9 -> -132924.6 | AD9: =COUNTIFS(Trades!$A$2:$A$2161,"SILVER",Trades!$B$2:$B$2161,"U9",Trades!$F$2:$F$2161,$A9) -> 19 | AE9: =IF(AD9=0,"",COUNTIFS(Trades!$A$2:$A$2161,"SILVER",Trades!$B$2:$B$2161,"U9",Trades!$F$2:$F$2161,$A9,Trades!$M$2:$M$2161,1)/AD9) -> 0.68421053 | AF9: =SUMIFS(Trades!$K$2:$K$2161,Trades!$A$2:$A$2161,"SILVER",Trades!$B$2:$B$2161,"U9",Trades!$F$2:$F$2161,$A9) -> -32210.4 | AG9: =AG8+AF9 -> 73695.6 | AH9: =COUNTIFS(Trades!$A$2:$A$2161,"SILVER",Trades!$B$2:$B$2161,"Q1",Trades!$F$2:$F$2161,$A9) -> 24 | AI9: =IF(AH9=0,"",COUNTIFS(Trades!$A$2:$A$2161,"SILVER",Trades!$B$2:$B$2161,"Q1",Trades!$F$2:$F$2161,$A9,Trades!$M$2:$M$2161,1)/AH9) -> 0.75 | AJ9: =SUMIFS(Trades!$K$2:$K$2161,Trades!$A$2:$A$2161,"SILVER",Trades!$B$2:$B$2161,"Q1",Trades!$F$2:$F$2161,$A9) -> -50085.3 | AK9: =AK8+AJ9 -> 23628.3
A10: 45809 | B10: =COUNTIFS(Trades!$A$2:$A$2161,"SILVER",Trades!$B$2:$B$2161,"V0",Trades!$F$2:$F$2161,$A10) -> 2 | C10: =IF(B10=0,"",COUNTIFS(Trades!$A$2:$A$2161,"SILVER",Trades!$B$2:$B$2161,"V0",Trades!$F$2:$F$2161,$A10,Trades!$M$2:$M$2161,1)/B10) -> 0.5 | D10: =SUMIFS(Trades!$K$2:$K$2161,Trades!$A$2:$A$2161,"SILVER",Trades!$B$2:$B$2161,"V0",Trades!$F$2:$F$2161,$A10) -> 108684.9 | E10: =E9+D10 -> -35601.6 | F10: =COUNTIFS(Trades!$A$2:$A$2161,"SILVER",Trades!$B$2:$B$2161,"V1",Trades!$F$2:$F$2161,$A10) -> 1 | G10: =IF(F10=0,"",COUNTIFS(Trades!$A$2:$A$2161,"SILVER",Trades!$B$2:$B$2161,"V1",Trades!$F$2:$F$2161,$A10,Trades!$M$2:$M$2161,1)/F10) -> 0 | H10: =SUMIFS(Trades!$K$2:$K$2161,Trades!$A$2:$A$2161,"SILVER",Trades!$B$2:$B$2161,"V1",Trades!$F$2:$F$2161,$A10) -> -80329.2 | I10: =I9+H10 -> -114077.4 | J10: =COUNTIFS(Trades!$A$2:$A$2161,"SILVER",Trades!$B$2:$B$2161,"W8",Trades!$F$2:$F$2161,$A10) -> 1 | K10: =IF(J10=0,"",COUNTIFS(Trades!$A$2:$A$2161,"SILVER",Trades!$B$2:$B$2161,"W8",Trades!$F$2:$F$2161,$A10,Trades!$M$2:$M$2161,1)/J10) -> 0 | L10: =SUMIFS(Trades!$K$2:$K$2161,Trades!$A$2:$A$2161,"SILVER",Trades!$B$2:$B$2161,"W8",Trades!$F$2:$F$2161,$A10) -> -80329.2 | M10: =M9+L10 -> -36511.2 | N10: =COUNTIFS(Trades!$A$2:$A$2161,"SILVER",Trades!$B$2:$B$2161,"W8C",Trades!$F$2:$F$2161,$A10) -> 0 | O10: =IF(N10=0,"",COUNTIFS(Trades!$A$2:$A$2161,"SILVER",Trades!$B$2:$B$2161,"W8C",Trades!$F$2:$F$2161,$A10,Trades!$M$2:$M$2161,1)/N10) | P10: =SUMIFS(Trades!$K$2:$K$2161,Trades!$A$2:$A$2161,"SILVER",Trades!$B$2:$B$2161,"W8C",Trades!$F$2:$F$2161,$A10) -> 0 | Q10: =Q9+P10 -> 22298.4 | R10: =COUNTIFS(Trades!$A$2:$A$2161,"SILVER",Trades!$B$2:$B$2161,"T6",Trades!$F$2:$F$2161,$A10) -> 3 | S10: =IF(R10=0,"",COUNTIFS(Trades!$A$2:$A$2161,"SILVER",Trades!$B$2:$B$2161,"T6",Trades!$F$2:$F$2161,$A10,Trades!$M$2:$M$2161,1)/R10) -> 0.66666667 | T10: =SUMIFS(Trades!$K$2:$K$2161,Trades!$A$2:$A$2161,"SILVER",Trades!$B$2:$B$2161,"T6",Trades!$F$2:$F$2161,$A10) -> -71605.5 | U10: =U9+T10 -> -130370.7 | V10: =COUNTIFS(Trades!$A$2:$A$2161,"SILVER",Trades!$B$2:$B$2161,"T7",Trades!$F$2:$F$2161,$A10) -> 4 | W10: =IF(V10=0,"",COUNTIFS(Trades!$A$2:$A$2161,"SILVER",Trades!$B$2:$B$2161,"T7",Trades!$F$2:$F$2161,$A10,Trades!$M$2:$M$2161,1)/V10) -> 0.75 | X10: =SUMIFS(Trades!$K$2:$K$2161,Trades!$A$2:$A$2161,"SILVER",Trades!$B$2:$B$2161,"T7",Trades!$F$2:$F$2161,$A10) -> -25314.9 | Y10: =Y9+X10 -> 26540.4 | Z10: =COUNTIFS(Trades!$A$2:$A$2161,"SILVER",Trades!$B$2:$B$2161,"U1",Trades!$F$2:$F$2161,$A10) -> 3 | AA10: =IF(Z10=0,"",COUNTIFS(Trades!$A$2:$A$2161,"SILVER",Trades!$B$2:$B$2161,"U1",Trades!$F$2:$F$2161,$A10,Trades!$M$2:$M$2161,1)/Z10) -> 0.66666667 | AB10: =SUMIFS(Trades!$K$2:$K$2161,Trades!$A$2:$A$2161,"SILVER",Trades!$B$2:$B$2161,"U1",Trades!$F$2:$F$2161,$A10) -> 33897 | AC10: =AC9+AB10 -> -99027.6 | AD10: =COUNTIFS(Trades!$A$2:$A$2161,"SILVER",Trades!$B$2:$B$2161,"U9",Trades!$F$2:$F$2161,$A10) -> 18 | AE10: =IF(AD10=0,"",COUNTIFS(Trades!$A$2:$A$2161,"SILVER",Trades!$B$2:$B$2161,"U9",Trades!$F$2:$F$2161,$A10,Trades!$M$2:$M$2161,1)/AD10) -> 0.44444444 | AF10: =SUMIFS(Trades!$K$2:$K$2161,Trades!$A$2:$A$2161,"SILVER",Trades!$B$2:$B$2161,"U9",Trades!$F$2:$F$2161,$A10) -> -78458.4 | AG10: =AG9+AF10 -> -4762.8 | AH10: =COUNTIFS(Trades!$A$2:$A$2161,"SILVER",Trades!$B$2:$B$2161,"Q1",Trades!$F$2:$F$2161,$A10) -> 13 | AI10: =IF(AH10=0,"",COUNTIFS(Trades!$A$2:$A$2161,"SILVER",Trades!$B$2:$B$2161,"Q1",Trades!$F$2:$F$2161,$A10,Trades!$M$2:$M$2161,1)/AH10) -> 0.69230769 | AJ10: =SUMIFS(Trades!$K$2:$K$2161,Trades!$A$2:$A$2161,"SILVER",Trades!$B$2:$B$2161,"Q1",Trades!$F$2:$F$2161,$A10) -> -6321.6 | AK10: =AK9+AJ10 -> 17306.7
